<?xml version="1.0" encoding="utf-8"?>
<!-- This URDF was automatically created by SolidWorks to URDF Exporter! Originally created by Stephen Brawner (brawner@gmail.com) 
     Commit Version: 1.6.0-4-g7f85cfe  Build Version: 1.6.7995.38578
     For more information, please see http://wiki.ros.org/sw_urdf_exporter -->
<robot
  name="Robot_ROS">
  <link
    name="base_link">
    <inertial>
      <origin
        xyz="0.010085 -7.8763E-06 -0.0066048"
        rpy="0 0 0" />
      <mass
        value="11.859" />
      <inertia
        ixx="0.01"
        ixy="0"
        ixz="0"
        iyy="0.01"
        iyz="0"
        izz="0.01" />
    </inertial>
    
    <visual>
      <origin
        xyz="0 0 0"
        rpy="0 0 0" />
      <geometry>
        <mesh
          filename="package://Robot_ROS/meshes/base_link.STL" />
      </geometry>
      <material
        name="">
        <color
          rgba="1 1 1 0.3" />
      </material>
    </visual>
    <collision>
      <origin
        xyz="0 0 0"
        rpy="0 0 0" />
      <geometry>
        <mesh
          filename="package://Robot_ROS/meshes/base_link.STL" />
      </geometry>
    </collision>
  </link>
  <link
    name="Right_Wheel_Link">
    <inertial>
      <origin
        xyz="-8.9146E-10 -3.2512E-08 0.011873"
        rpy="0 0 0" />
      <mass
        value="7.021404" />
      <inertia
        ixx="0.0005"
        ixy="0"
        ixz="0"
        iyy="0.0002"
        iyz="0"
        izz="0.0008"  />
    </inertial>
    <visual>
      <origin
        xyz="0 0 0"
        rpy="0 0 0" />
      <geometry>
        <mesh
          filename="package://Robot_ROS/meshes/Right_Wheel_Link.STL" />
      </geometry>
      <material
        name="">
        <color
          rgba="0.79216 0.81961 0.93333 1" />
      </material>
    </visual>
    <collision>
      <origin
        xyz="0 0 0"
        rpy="0 0 0" />
      <geometry>
        <mesh
          filename="package://Robot_ROS/meshes/Right_Wheel_Link.STL" />
      </geometry>
    </collision>
  </link>
  <joint
    name="Right_Wheel_Joint"
    type="continuous">
    <origin
      xyz="-0.033259 -0.08025 -0.01375"
      rpy="1.5708 0.042481 -3.1416" />
    <parent
      link="base_link" />
    <child
      link="Right_Wheel_Link" />
    <axis
      xyz="0 0 1" />
    <limit
      effort="100"
      velocity="100" />
    <dynamics
      damping="0.1"
      friction="0.1" />
  </joint>
  <link
    name="Left_Wheel_Link">
    <inertial>
      <origin
        xyz="8.9146E-10 -3.2512E-08 -0.011873"
        rpy="0 0 0" />
      <mass
        value="7.021404" />
      <inertia
        ixx="0.05"
        ixy="0"
        ixz="0"
        iyy="0.02"
        iyz="0"
        izz="0.08" />
    </inertial>
    <visual>
      <origin
        xyz="0 0 0"
        rpy="0 0 0" />
      <geometry>
        <mesh
          filename="package://Robot_ROS/meshes/Left_Wheel_Link.STL" />
      </geometry>
      <material
        name="">
        <color
          rgba="0.79216 0.81961 0.93333 1" />
      </material>
    </visual>
    <collision>
      <origin
        xyz="0 0 0"
        rpy="0 0 0" />
      <geometry>
        <mesh
          filename="package://Robot_ROS/meshes/Left_Wheel_Link.STL" />
      </geometry>
    </collision>
  </link>
  <joint
    name="Left_Wheel_Joint"
    type="continuous">
    <origin
      xyz="-0.033259 0.08025 -0.01375"
      rpy="-1.5708 0.042481 0" />
    <parent
      link="base_link" />
    <child
      link="Left_Wheel_Link" />
    <axis
      xyz="0 0 1" />
    <limit
      effort="100"
      velocity="100" />
    <dynamics
      damping="0.1"
      friction="0.1" />
  </joint>
  <link
    name="Base_Bieber_Link">
    <inertial>
      <origin
        xyz="0 0 0"
        rpy="0 0 0" />
      <mass
        value="0.002" />
      <inertia
        ixx="0.0001"
        ixy="0"
        ixz="0"
        iyy="0.0001"
        iyz="0"
        izz="0.0001" />
    </inertial>
    <visual>
      <origin
        xyz="0 0 0"
        rpy="0 0 0" />
      <geometry>
        <mesh
          filename="package://Robot_ROS/meshes/Base_Bieber_Link.STL" />
      </geometry>
      <material
        name="">
        <color
          rgba="1 1 1 1" />
      </material>
    </visual>
    <collision>
      <origin
        xyz="0 0 0"
        rpy="0 0 0" />
      <geometry>
        <mesh
          filename="package://Robot_ROS/meshes/Base_Bieber_Link.STL" />
      </geometry>
    </collision>
  </link>
  <joint
    name="Base_Bieber_Joint"
    type="fixed">
    <origin
      xyz="0.072581 0 -0.0025"
      rpy="-3.1408 0 0" />
    <parent
      link="base_link" />
    <child
      link="Base_Bieber_Link" />
    <axis
      xyz="0 0 1" />
    <limit
      lower="0"
      upper="0"
      effort="100"
      velocity="100" />
    <dynamics
      damping="0.1"
      friction="0.1" />
  </joint>
  <link
    name="Bieber_Wheel_Link">
    <inertial>
      <origin
        xyz="6.9389E-18 -2.6204E-11 -2.7771E-09"
        rpy="0 0 0" />
      <mass
        value="0.082874" />
      <inertia
        ixx="0.0005"
        ixy="0"
        ixz="0"
        iyy="0.0002"
        iyz="0"
        izz="0.0008"  />
    </inertial>
    <visual>
      <origin
        xyz="0 0 0"
        rpy="0 0 0" />
      <geometry>
        <mesh
          filename="package://Robot_ROS/meshes/Bieber_Wheel_Link.STL" />
      </geometry>
      <material
        name="">
        <color
          rgba="1 1 1 1" />
      </material>
    </visual>
    <collision>
      <origin
        xyz="0 0 0"
        rpy="0 0 0" />
      <geometry>
        <mesh
          filename="package://Robot_ROS/meshes/Bieber_Wheel_Link.STL" />
      </geometry>
    </collision>
  </link>
  <joint
    name="Bieber_Wheel_Joint"
    type="continuous">
    <origin
      xyz="0.015014 -0.00012272 0.02296"
      rpy="0 -1.57 1.5708" />
    <parent
      link="Base_Bieber_Link" />
    <child
      link="Bieber_Wheel_Link" />
    <axis
      xyz="0 0 1" />
    <limit
      lower="0"
      upper="0"
      effort="100"
      velocity="100" />
    <dynamics
      damping="0.1"
      friction="0.1" />
  </joint>
    <!-- Base_Bieber_Link and Bieber_Wheel_Link definitions -->
  <!-- Add other links and joints here -->
  <link name="camera_link">
    <inertial>
      <mass value="0.5"/>
      <origin 
      xyz="0 0 0"
      rpy="0 0 0"/>
      <inertia 
      ixx="0.00005"
      ixy="0" 
      ixz="0" 
      iyy="0.00003" 
      iyz="0" 
      izz="0.00008"/>
    </inertial>
    <visual>
      <origin 
      xyz="0 0 0"
      rpy="0 0 0"/>
      <geometry>
        <box 
        size="0.01 0.01 0.01"/>
      </geometry>
      <material 
        name="">
        <color 
          rgba="1.0 0.5 0.5 0.5"/>
      </material>
    </visual>
    <collision>
      <origin 
      xyz="0 0 0" 
      rpy="0 0 0"/>
      <geometry>
        <box 
        size="0.01 0.01 0.01"/>
      </geometry>
    </collision>
  </link>
  <joint 
  name="camera_joint" 
  type="fixed">
    <parent 
    link="base_link"/>
    <child 
    link="camera_link"/>
    <origin 
    
    xyz="0.052 0 0.41" 
    rpy="0 1.13 0"/>
  </joint>
  <!-- xyz="0.052 0 0.41" 
    rpy="0 1.13 0"/> -->
  <!-- <link name="radar_link">
    <inertial>
      <mass value="0.05"/>
      <origin 
      xyz="0 0 0"
      rpy="0 0 0"/>
      <inertia 
      ixx="0.00005"
      ixy="0" 
      ixz="0" 
      iyy="0.00003" 
      iyz="0" 
      izz="0.00008"/>
    </inertial>
    <visual>
      <origin 
      xyz="1 1 1"
      rpy="1 1 1"/>
      <geometry>
        <box 
        size="0.01 0.01 0.01"/>
      </geometry>
      <material 
        name="">
        <color 
          rgba="0 0 0 0"/>
      </material>
    </visual>
    <collision>
      <origin 
      xyz="0 0 0" 
      rpy="0 0 0"/>
      <geometry>
        <box 
        size="0.01 0.01 0.01"/>
      </geometry>
    </collision>
  </link>
  <joint 
  name="radar_joint" 
  type="fixed">
    <parent 
    link="base_link"/>
    <child 
    link="radar_link"/>
    <origin 
    xyz="0.05 0 0.01" 
    rpy="0 0 0"/>
  </joint> -->
  
  
  
  <!-- Differential drive plugin -->
<gazebo>
  <plugin name="two_wheeled_robot_diff_drive" filename="libgazebo_ros_diff_drive.so">
    <updateRate>50</updateRate>

    <!-- wheels -->
    <leftJoint>Left_Wheel_Joint</leftJoint>
    <rightJoint>Right_Wheel_Joint</rightJoint>

    <!-- kinematics -->
    <wheelSeparation>0.15</wheelSeparation>
    <wheelDiameter>0.06</wheelDiameter>

    <!-- limits -->
    <max_wheel_torque>10</max_wheel_torque>
    <max_wheel_acceleration>10.0</max_wheel_acceleration>

    <!-- Receive velocity commands on this ROS topic -->
    <commandTopic>cmd_vel</commandTopic>

    <!-- output -->
    <publishOdom>true</publishOdom>
    <publishOdomTF>true</publishOdomTF>
    <publishWheelTF>true</publishWheelTF>
    <publishWheelJointState>true</publishWheelJointState>

    <odometryTopic>odom</odometryTopic>
    <odometryFrame>odom</odometryFrame>
    <robotBaseFrame>base_link</robotBaseFrame>

    <odometrySource>1</odometrySource>
  </plugin>
</gazebo>

<gazebo>
    <plugin name="gazebo_ros_joint_state_publisher"
        filename="libgazebo_ros_joint_state_publisher.so">
        <update_rate>50</update_rate>
        <joint_name>Base_Bieber_Joint</joint_name>
        <joint_name>Bieber_Wheel_Link</joint_name>
    </plugin>
</gazebo>

<gazebo reference="camera_link">
  <material>Gazebo/Red</material>
  <sensor name="camera" type="camera">
    <pose> 0 0 0 0 0 0 </pose>
    <visualize>true</visualize>
    <update_rate>10</update_rate>
    <camera>
      <horizontal_fov>1.0</horizontal_fov>
      <image>
          <format>B8G8R8</format>
          <width>900</width>
          <height>270</height>
      </image>
      <clip>
        <near>0.05</near>
        <far>8.0</far>
      </clip>
    </camera>
    <plugin name="camera_controller" filename="libgazebo_ros_camera.so">
      <frame_name>camera_link_optical</frame_name>
    </plugin>
  </sensor>
  

  <!-- <sensor name="camera" type="camera">
    <pose> 0 0 0 0 0 </pose>
    <visualize>true</visualize>
    <update_rate>10</update_rate>
    <camera>  
      <horizontal_fov>1.0</horizontal_fov>
      <image>
          <format>B8G8R8</format>
          <width>640</width>
          <height>200</height>
      </image>
      <clip>
        <near>0.05</near>
        <far>8.0</far>
      </clip>
    </camera>
    <plugin name="camera_controller" filename="libgazebo_ros_camera.so">
      <topicName>/camera_scan</topicName>
      <frame_name>camera_link_optical</frame_name>
    </plugin>
  </sensor> -->
</gazebo>



  
<!-- <gazebo reference="base_link">
    <sensor type="ray" name="radar_sensor">
      <pose>0 0 0 0 -0.069 0</pose>
      <visualize>true</visualize>
      <update_rate>10</update_rate>
      <ray>
        <scan>
          <horizontal>
            <samples>1000</samples>
            <resolution>1</resolution>
            <min_angle>-3.14159265</min_angle> 
            <max_angle>3.14159265</max_angle>
          </horizontal>
        </scan>
        <range>
          <min>0.3</min>
          <max>15</max>
          <resolution>0.01</resolution>
        </range>
        <noise>
          <type>gaussian</type>
          <mean>0.0</mean>
          <stddev>0.01</stddev>
        </noise>
      </ray>
      <plugin name="radar_sensor_plugin" filename="ModeCRadarPlugin">
        <topicName>/radar_scan</topicName>
        <frameName>radar_link_base</frameName>
      </plugin>
    </sensor>
</gazebo>   -->


<gazebo reference="base_link">
  <sensor type="ray" name="radar_sensor">
    <pose>0 0 0 0 -0.069 0</pose>
    <visualize>true</visualize>
    <update_rate>10</update_rate>
    <ray>
      <scan>
        <horizontal>
          <samples>360</samples>
          <resolution>1</resolution>
          <min_angle>-1.57</min_angle> 
          <max_angle>1.57</max_angle>
        </horizontal>
        <vertical>
          <samples>1</samples>
          <resolution>1</resolution>
          <min_angle>0</min_angle>
          <max_angle>0</max_angle>
        </vertical>
      </scan>
      <range>
        <min>0.22</min>
        <max>2.5</max>
        <resolution>0.01</resolution>
      </range>
      <noise>
        <type>gaussian</type>
        <mean>0.0</mean>
        <stddev>0.05</stddev>
      </noise>
    </ray>
    <plugin name="radar_sensor_plugin" filename="libgazebo_ros_laser.so">
      <topicName>/radar_scan</topicName>
      <frameName>radar_link</frameName>
    </plugin>
  </sensor>
</gazebo>


  
</robot>
